<?xml version="1.0" ?>
<!-- =================================================================================== -->
<!-- |    This document was autogenerated by xacro from spombob.xacro                  | -->
<!-- |    EDITING THIS FILE BY HAND IS NOT RECOMMENDED                                 | -->
<!-- =================================================================================== -->
<robot name="spongebob">
  <!-- distance between center of left and right wheels-->
  <material name="grey">
    <color rgba="0.75 0.75 0.75 1"/>
  </material>
  <material name="blue">
    <color rgba="0 0 1 1"/>
  </material>
  <material name="black">
    <color rgba="0 0 0 1"/>
  </material>
  <material name="red">
    <color rgba="1 0 0 1"/>
  </material>
  <!-- Robot Base -->
  <link name="base_link">
    <collision>
      <geometry>
        <box size="0.52 0.4 0.1"/>
      </geometry>
      <origin rpy="0 0 0" xyz="0.26 0 0.2"/>
    </collision>
    <visual>
      <geometry>
        <box size="0.52 0.4 0.1"/>
      </geometry>
      <origin rpy="0 0 0" xyz="0.26 0 0.2"/>
      <material name="grey"/>
    </visual>
  </link>
  <!-- Robot Footprint -->
  <link name="base_footprint"/>
  <joint name="base_joint" type="fixed">
    <parent link="base_link"/>
    <child link="base_footprint"/>
    <origin rpy="0 0 0" xyz="0.26 0.0 0.0"/>
  </joint>
  <link name="marking_base"/>
  <joint name="marking_base_joint" type="fixed">
    <parent link="marking_base"/>
    <child link="base_link"/>
    <origin rpy="0 0 0" xyz="0.0 0.0 0.0"/>
  </joint>
  <link name="marking_spot">
    <visual>
      <geometry>
        <cylinder length="0.001" radius="0.01"/>
      </geometry>
      <origin rpy="0 0 0" xyz="0 0 0"/>
      <material name="red"/>
    </visual>
  </link>
  <joint name="marking_joint" type="fixed">
    <parent link="marking_spot"/>
    <child link="marking_base"/>
    <origin rpy="0 0 0" xyz="0.0 0.0 0.0"/>
  </joint>
  <link name="caster">
    <collision>
      <origin rpy="0 0 0" xyz="0 0 0"/>
      <geometry>
        <sphere radius="0.065"/>
      </geometry>
    </collision>
    <visual>
      <origin rpy="0 0 0" xyz="0 0 0"/>
      <geometry>
        <sphere radius="0.065"/>
      </geometry>
      <material name="black"/>
    </visual>
  </link>
  <joint name="caster_joint" type="continuous">
    <parent link="base_link"/>
    <child link="caster"/>
    <origin rpy="0 0 0" xyz="0.47000000000000003 0 0.065"/>
    <axis xyz="0 1 1"/>
  </joint>
  <link name="bl_wheel">
    <collision>
      <origin rpy="1.5707963267948966 0 0" xyz="0 0 0"/>
      <geometry>
        <cylinder length="0.08" radius="0.13"/>
      </geometry>
    </collision>
    <visual>
      <origin rpy="1.5707963267948966 0 0" xyz="0 0 0"/>
      <geometry>
        <cylinder length="0.08" radius="0.13"/>
      </geometry>
      <material name="black"/>
    </visual>
  </link>
  <joint name="bl_wheel_joint" type="continuous">
    <parent link="base_link"/>
    <child link="bl_wheel"/>
    <origin rpy="0 0 0" xyz="0.0 0.25 0.13"/>
    <axis xyz="0 1 0"/>
  </joint>
  <link name="br_wheel">
    <collision>
      <origin rpy="1.5707963267948966 0 0" xyz="0 0 0"/>
      <geometry>
        <cylinder length="0.08" radius="0.13"/>
      </geometry>
    </collision>
    <visual>
      <origin rpy="1.5707963267948966 0 0" xyz="0 0 0"/>
      <geometry>
        <cylinder length="0.08" radius="0.13"/>
      </geometry>
      <material name="black"/>
    </visual>
  </link>
  <joint name="br_wheel_joint" type="continuous">
    <parent link="base_link"/>
    <child link="br_wheel"/>
    <origin rpy="0 0 0" xyz="0.0 -0.25 0.13"/>
    <axis xyz="0 1 0"/>
  </joint>
</robot>
